Workbook
Name actualshearstress: ShearCheck!$I$13
Name Ast: 'Deflection control'!$E$33
Name Ast_ln_span: 'Backup cal for Mul & Xul'!$H$49
Name Ast_ln_supp: 'Backup cal for Mul & Xul'!$I$49
Name Ast_sh_span: 'Backup cal for Mul & Xul'!$F$49
Name Ast_sh_supp: 'Backup cal for Mul & Xul'!$G$49
Name astmin: 'Design of Slab'!$C$34
Name b: 'Backup cal for Mul & Xul'!$D$4
Name Check: 'Backup cal for Mul & Xul'!$B$35
Name Condition: 'Support Index'!$H$25
Name cover: 'Default values'!$E$10
Name d: 'Backup cal for Mul & Xul'!$D$20
Name deff: 'Backup cal for Mul & Xul'!$D$20
Name deff_1: 'Backup cal for Mul & Xul'!$F$41
Name deff_2: 'Backup cal for Mul & Xul'!$G$41
Name deff_3: 'Backup cal for Mul & Xul'!$H$41
Name deff_4: 'Backup cal for Mul & Xul'!$I$41
Name density: 'Default values'!$E$11
Name DL: 'Design of Slab'!$D$22
Name dreqd: 'Backup cal for Mul & Xul'!$E$19
Name Ec: 'Default values'!$E$9
Name Es: 'Default values'!$E$8
Name fck: 'Design of Slab'!$D$14
Name fs: 'Deflection control'!$E$32
Name fy: 'Design of Slab'!$D$15
Name Icr: 'Actual deflection'!$K$16
Name Ie: 'Actual deflection'!$K$24
Name Ig: 'Actual deflection'!$K$17
Name K: ShearCheck!$I$23
Name LL: 'Design of Slab'!$D$23
Name Lx: 'Design of Slab'!$D$8
Name Ly: 'Design of Slab'!$D$7
Name m: 'Default values'!$E$12
Name MF: 'Deflection control'!$E$34
Name Mu_ln_span: 'Design of Slab'!$E$31
Name Mu_ln_supp: 'Design of Slab'!$F$31
Name Mu_sh_span: 'Design of Slab'!$C$31
Name Mu_sh_supp: 'Design of Slab'!$D$31
Name Mul: 'Backup cal for Mul & Xul'!$B$33
Name Mumax: 'Backup cal for Mul & Xul'!$D$3
Name pt_ln_sp: ShearCheck!$F$21
Name pt_ln_sup: ShearCheck!$G$21
Name pt_s_sp: ShearCheck!$D$21
Name pt_s_sup: ShearCheck!$E$21
Name ratio: 'Design of Slab'!$J$13
Name Remarks: 'Backup cal for Mul & Xul'!$B$34
Name shearpt: ShearCheck!$D$22
Name spanbydepth: 'Deflection control'!$E$36
Name T: 'Design of Slab'!$D$9
Name Tauc: 'Table-19'!$K$9
Name Vu: ShearCheck!$I$11
Name w: 'Design of Slab'!$D$24
Name Wult: 'Design of Slab'!$D$25
Name xu: 'Backup cal for Mul & Xul'!$F$48
Name xul: 'Backup cal for Mul & Xul'!$D$31
Name xul_coeff: 'Backup cal for Mul & Xul'!$D$30

Sheet Design of Slab
E1: Project:-
E2: Prepared By: | H2: Date:- | I2: =TODAY() -> 45692
E3: Location:- | F3: S1 (CONCOURSE LEVEL)
A4: DESIGN OF SLAB
A5: Legend:- | C5: : To give input
A6: A. DIMENSIONS | G6: B. INPUT FOR SUPPORT CONDITION
A7: Longer span: Ly = | D7: 4 | E7: m
A8: Shorter span : Lx= | D8: 3 | E8: m
A9: Thickness of the slab : T | D9: 150 | E9: mm
A10: Required thickness (to start with) | D10: =IF('Deflection control'!E38>0,MAX(dreqd,'Deflection control'!E38),dreqd) -> 116.95652 | E10: mm | J10: Lx
A11: Clear cover to main reinf. | D11: 25 | E11: mm
A13: C. MATERIAL | G13: Span ratio Ly / Lx = | J13: =Ly/Lx -> 1.3333333
A14: Grade of Concrete : fck | D14: 25 | E14: N/mm2 | G14: Edges | I14: Continuous
A15: Grade of Reinforcement Steel : fy | D15: ='Default values'!E7 -> 500 | E15: N/mm2 | G15: Long Sides | H15: Upper edge | I15: 1 | J15: 1 if Yes and 2 if No
A16: Density of reinforced concrete | D16: =density -> 25 | E16: KN/m3 | H16: Lower edge | I16: 1
G17: Short Sides | H17: Left edge | I17: 2
A18: D. LOADING | H18: Right edge | I18: 2
A19: Self weight of slab | D19: 6.25 | E19: KN/m2 | G19: ='Support Index'!H25 -> Cond-4
A20: Finish on the slab | D20: 5.4 | E20: KN/m2 | G20: ='Support Index'!H26 -> Two short edges discontinuous
A21: Other load ( if any) | D21: 0 | E21: KN/m2 | G21: Effective depth : deff in mm | J21: =d -> 120
A22: Total Dead Load : DL | D22: =SUM(D19:D21) -> 11.65 | E22: KN/m2 | G22: Error Message on Input Data (if any)
A23: Live Load : LL | D23: 5 | E23: KN/m2 | G23: A. Dimensions | I23: =IF(Ly<=0,"Ly should be >0",IF(Lx<=0, "Lx should be >0",IF(T<=0,"Thickness should be >0",IF(Ly<Lx,"Check, Lx>Ly","None")))) -> None
A24: Total UDL : w =DL + LL | D24: =DL+LL -> 16.65 | E24: KN/m2 | G24: B. Support Condition | I24: =IF(G19=FALSE, "Values should be 1or 2","None") -> None
A25: Total Ultimate UDL : 1.5(DL + LL) | D25: =1.5*w -> 24.975 | E25: KN/m2 | G25: D. Loading | I25: =IF(D20< 0,"load should be =>0",IF(D21<0, "Load should be =>0",IF(LL<0,"LL should be =>0","None"))) -> None
A26: =IF(ratio>2," THIS IS A ONE WAY SLAB", " THIS IS A TWO WAY SLAB") -> THIS IS A TWO WAY SLAB
A27: E. DESIGN | G27: FINAL OUTPUT
C28: Short Span | E28: Long Span
C29: at span | D29: at support | E29: at span | F29: at support
A30: Moment Coeff. | C30: ='Moment Coeff'!F5 -> 0.044 | D30: ='Moment Coeff'!G5 -> 0.059 | E30: ='Moment Coeff'!H5 -> 0.035 | F30: ='Moment Coeff'!I5 -> 0
A31: Ult. Moment: Mu in Kn-m | C31: =C30*Wult*Lx^2 -> 9.8901 | D31: =D30*Wult*Lx^2 -> 13.261725 | E31: =E30*Wult*Lx^2 -> 7.867125 | F31: =F30*Wult*Lx^2 -> 0 | G31: =" T"&F36&"@"&F40&"c/c" -> T10@175c/c | I31: ="T"&C36&"@"&C40&"c/c" -> T10@175c/c
A32: ="Remarks :"&Remarks -> Remarks : It has been designed as under-reinforced section | J32: ="T"&E36&"@"&E40&"c/c" -> T10@175c/c
A33: Required Ast (mm^2) | C33: =Ast_sh_span -> 195.90266 | D33: =Ast_sh_supp -> 268.43351 | E33: =Ast_ln_span -> 155.54074 | F33: =Ast_ln_supp -> 0
A34: Minimum Ast (mm^2) | C34: =0.12/100*b*d -> 144 | I34: ="T"&D36&"@"&D40&"c/c" -> T10@175c/c
A35: Design reinforcement | C35: =IF(C33<astmin,astmin,C33) -> 195.90266 | D35: =IF(D33<astmin,astmin,D33) -> 268.43351 | E35: =IF(E33<astmin,astmin,E33) -> 155.54074 | F35: =IF(F33<astmin,astmin,F33) -> 144
A36: Diameter of the bar | C36: 10 | D36: 10 | E36: 10 | F36: 10
A37: Required spacing | C37: =(PI()/4*C36^2*1000/C35) -> 400.91245 | D37: =(PI()/4*D36^2*1000/D35) -> 292.58574 | E37: =(PI()/4*E36^2*1000/E35) -> 504.9469 | F37: =(PI()/4*F36^2*1000/F35) -> 545.41539 | G37: ="Overall Thickness of the slab is "&T&" mm" -> Overall Thickness of the slab is 150 mm
A38: Allowable min spacing | C38: =MAX((MAX(C36,D36,E36,F36)),(20+5))+MAX(C36,D36,E36,F36) -> 35
A39: Allowable max spacing | C39: =MIN(3*d,300) -> 300 | D39: =MIN(3*d,300) -> 300 | E39: =MIN(3*d,300) -> 300 | F39: =MIN(3*d,300) -> 300 | H39: Final Status | I39: =IF(Checks!E11=0,"O.K","NOT O.K") -> O.K
A40: Spacing provided | C40: 175 | D40: 175 | E40: 175 | F40: 175 | G40: =IF(J44>J45,"To check shear you may also try to increase reinf at supports"," ")
A41: Check | C41: =IF(C40<=C37,IF(C40>=$C$38,IF(C40<=C39,"O.K","Not O.K"),"Not O.K"),"Not O.K") -> O.K | D41: =IF(D40<=D37,IF(D40>$C$38,IF(D40<D39,"O.K", "Not O.K"),"Not O.K"), "Not O.K") -> O.K | E41: =IF(E40<=E37,IF(E40>$C$38,IF(E40<E39,"O.K", "Not O.K"),"Not O.K"), "Not O.K") -> O.K | F41: =IF(F40<=F37,IF(F40>$C$38,IF(F40<F39,"O.K", "Not O.K"),"Not O.K"), "Not O.K") -> O.K
...

Sheet Default values
A1: Default Values
A3: Following are the default values considered in the Design unless separate input values are given
A5: Item | E5: Value as considered | F5: Input value (if any)
A6: Grade of Concrete in N/mm2 | E6: =IF(F6>0,F6,30) -> 50 | F6: 50
A7: Grade of Reinforcement Steel in N/mm2 | E7: =IF(F7>0,F7,415) -> 500 | F7: 500
A8: Elastic Modulus of reinf. Steel Es N/mm2 | E8: =IF(F8>0,F8,200000) -> 200000
A9: Elastic Modulus of Concrete Ec N/mm2 | E9: =IF(F9>0,F9,5000*SQRT(fck)) -> 25000
A10: Clear cover to the main reinforcement | E10: =IF(F10>0,F10,20) -> 25 | F10: 25
A11: Density of concrete in N/mm^3 | E11: =IF(F11>0,F11,25) -> 25
A12: Modular ratio= Es/Ec | E12: =Es/E9 -> 8

Sheet Costing
A1: Bill of Quantity
A3: Volume of Concrete Used = | D3: =Lx*Ly*T/1000 -> 1.8 | E3: m3
A4: Shuttering = | D4: =Ly*Lx -> 12 | E4: m^2
A5: Reinforcement calculation
D6: Short Span | G6: Long Span | J6: TOTAL WEIGHT
D7: at span | E7: at support | F7: distribution | G7: at span | H7: at support | I7: distribution
A8: Diameter of the bar = | D8: ='Design of Slab'!C36 -> 10 | E8: ='Design of Slab'!D36 -> 10 | F8: 8 | G8: ='Design of Slab'!E36 -> 10 | H8: ='Design of Slab'!F36 -> 10 | I8: 8
A9: Spacing of the bars in mm= | D9: ='Design of Slab'!C40 -> 175 | E9: ='Design of Slab'!D40 -> 175 | F9: =MIN(5*d,250) -> 250 | G9: ='Design of Slab'!E40 -> 175 | H9: ='Design of Slab'!F40 -> 175 | I9: =MIN(5*d,250) -> 250
A10: Length of the bar in m= | D10: =Lx -> 3 | E10: =Lx/3 -> 1 | F10: =Ly -> 4 | G10: =Ly -> 4 | H10: =Ly/3 -> 1.3333333 | I10: =Lx -> 3
A11: Number of the bar= | D11: =CEILING(Ly*1000/D9,1) -> 23 | E11: =CEILING(Ly*1000/E9,1)*2 -> 46 | F11: =(CEILING(E10*1000/F9,1))*2 -> 8 | G11: =CEILING(Lx*1000/G9,1) -> 18 | H11: =2*CEILING(Lx*1000/H9,1) -> 36 | I11: =2*CEILING(H10*1000/I9,1) -> 12
A12: Weight of the bar in Kg/m= | D12: =PI()/4*D8^2*1000*7.85*0.000001 -> 0.61653756 | E12: =PI()/4*E8^2*1000*7.85*0.000001 -> 0.61653756 | F12: =PI()/4*F8^2*1000*7.85*0.000001 -> 0.39458404 | G12: =PI()/4*G8^2*1000*7.85*0.000001 -> 0.61653756 | H12: =PI()/4*H8^2*1000*7.85*0.000001 -> 0.61653756 | I12: =PI()/4*I8^2*1000*7.85*0.000001 -> 0.39458404
A13: Weight of the bar in Kg= | D13: =D10*D11*D12 -> 42.541092 | E13: =E10*E11*E12 -> 28.360728 | F13: =F10*F11*F12 -> 12.626689 | G13: =G10*G11*G12 -> 44.390704 | H13: =H10*H11*H12 -> 29.593803 | I13: =I10*I11*I12 -> 14.205025 | J13: =SUM(D13:I13) -> 171.71804 | K13: Kg
A14: weight of steel per cubic m of concrete | J14: =J13/D3 -> 95.398912 | K14: Kg/m^3
A16: ESTIMATION
A17: Sl. No. | B17: Item Description | E17: Unit | F17: Quantity | G17: Default Rate | H17: Input Rate | I17: Amount(Rs.)
A18: 1 | B18: Volume of concrete | E18: Cu.m | F18: =D3 -> 1.8 | G18: 3000 | I18: =IF(H18>0,F18*H18,F18*G18) -> 5400
A19: 2 | B19: Shuttering | E19: Sq. m | F19: =D4 -> 12 | G19: 150 | I19: =IF(H19>0,F19*H19,F19*G19) -> 1800
A20: 3 | B20: Reinforcement steel | E20: Kg | F20: =J13 -> 171.71804 | G20: 35 | I20: =IF(H20>0,F20*H20,F20*G20) -> 6010.1314
A21: Total | I21: =SUM(I18:I20) -> 13210.131
A22: Total per sq.m area | I22: =I21/(Ly*Lx) -> 1100.8443

Sheet Support Index
B1: INDEX CALCULATION FOR SUPPORT CONDITION
B2: Index for the slab panel under consideration | I2: Error
C3: ='Design of Slab'!I15 -> 1 | D3: ='Design of Slab'!I16 -> 1 | E3: ='Design of Slab'!I17 -> 2 | F3: ='Design of Slab'!I18 -> 2 | G3: ='Design of Slab'!I15*1000+'Design of Slab'!I16*100+'Design of Slab'!I17*10+'Design of Slab'!I18 -> 1122 | H3: =C3*1000+D3*100+E3*10+F3 -> 1122 | I3: =G3-H3 -> 0
K4: Support Condition
C5: Long side Ly | E5: Short side Lx | G5: Index
C6: Upper side | D6: Lower side | E6: Left side | F6: Right side
A7: Cond-1 | B7: All edges discontinuous | C7: 2 | D7: 2 | E7: 2 | F7: 2 | G7: =C7*1000+D7*100+E7*10+F7 -> 2222 | H7: =IF($G$3=G7,A7," ")
A8: Cond-2 | B8: All edges continuous | C8: 1 | D8: 1 | E8: 1 | F8: 1 | G8: =C8*1000+D8*100+E8*10+F8 -> 1111 | H8: =IF($G$3=G8,A8," ") | M8: Lx
A9: Cond-3 | B9: Two long edges discontinuous | C9: 2 | D9: 2 | E9: 1 | F9: 1 | G9: =C9*1000+D9*100+E9*10+F9 -> 2211 | H9: =IF($G$3=G9,A9," ")
A10: Cond-4 | B10: Two short edges discontinuous | C10: 1 | D10: 1 | E10: 2 | F10: 2 | G10: =C10*1000+D10*100+E10*10+F10 -> 1122 | H10: =IF($G$3=G10,A10," ") -> Cond-4
A11: Cond-5 | B11: Two adjacent edges discontinuous | C11: 2 | D11: 1 | E11: 1 | F11: 2 | G11: =C11*1000+D11*100+E11*10+F11 -> 2112 | H11: =IF($G$3=G11,A11,IF($G$3=G12,A11,IF($G$3=G13,A11,IF($G$3=G14,A11," "))))
C12: 2 | D12: 1 | E12: 2 | F12: 1 | G12: =C12*1000+D12*100+E12*10+F12 -> 2121 | L12: Continuous
C13: 1 | D13: 2 | E13: 1 | F13: 2 | G13: =C13*1000+D13*100+E13*10+F13 -> 1212 | K13: Upper side | L13: =C3 -> 1 | M13: 1 if Yes and 2 if No
C14: 1 | D14: 2 | E14: 2 | F14: 1 | G14: =C14*1000+D14*100+E14*10+F14 -> 1221 | K14: Lower side | L14: =D3 -> 1
A15: Cond-6 | B15: Only one long edge discontinuous | C15: 2 | D15: 1 | E15: 1 | F15: 1 | G15: =C15*1000+D15*100+E15*10+F15 -> 2111 | H15: =IF($G$3=G15,A15,IF($G$3=G16,A15," ")) | K15: Left side | L15: =E3 -> 2
C16: 1 | D16: 2 | E16: 1 | F16: 1 | G16: =C16*1000+D16*100+E16*10+F16 -> 1211 | K16: Right side | L16: =F3 -> 2
A17: Cond-7 | B17: Only one short edge discontinuous | C17: 1 | D17: 1 | E17: 2 | F17: 1 | G17: =C17*1000+D17*100+E17*10+F17 -> 1121 | H17: =IF($G$3=G17,A17,IF($G$3=G18,A17," ")) | L17: =L13*1000+L14*100+L15*10+L16 -> 1122
C18: 1 | D18: 1 | E18: 1 | F18: 2 | G18: =C18*1000+D18*100+E18*10+F18 -> 1112
B19: Intermediate level summation as nested logical function "if" more than 7 level is not valid | H19: =IF(H7<>" ",H7,IF(H8<>" ",H8,IF(H9<>" ",H9,IF(H10<>" ",H10,IF(H11<>" ",H11,IF(H15<>" ",H15,IF(H17<>" ",H17," "))))))) -> Cond-4
H20: =IF($H$19=A7,B7,IF($H$19=A8,B8,IF($H$19=A9,B9,IF($H$19=A10,B10,IF($H$19=A11,B11,IF($H$19=A15,B15,IF($H$19=A17,B17," "))))))) -> Two short edges discontinuous
A21: Cond-8 | B21: Only one short edge continuous | C21: 2 | D21: 2 | E21: 2 | F21: 1 | G21: =C21*1000+D21*100+E21*10+F21 -> 2221 | H21: =IF($G$3=G21,A21,IF($G$3=G22,A21," "))
C22: 2 | D22: 2 | E22: 1 | F22: 2 | G22: =C22*1000+D22*100+E22*10+F22 -> 2212
A23: Cond-9 | B23: Only one long edge continuous | C23: 1 | D23: 2 | E23: 2 | F23: 2 | G23: =C23*1000+D23*100+E23*10+F23 -> 1222 | H23: =IF($G$3=G23,A23,IF($G$3=G24,A23," "))
C24: 2 | D24: 1 | E24: 2 | F24: 2 | G24: =C24*1000+D24*100+E24*10+F24 -> 2122
H25: =IF(H19<>" ",H19,IF(H21<>" ",H21,IF(H23<>" ",H23))) -> Cond-4
H26: =IF($H$25=H19,H20,IF($H$25=A21,B21,IF($H$25=A23,B23))) -> Two short edges discontinuous

Sheet Checks
B3: Shear Check | D3: =IF('Design of Slab'!J44<='Design of Slab'!J45,"O.K") -> O.K | E3: =IF(D3="O.K",0,1) -> 0
B4: Balance section | D4: =IF(Mul>=Mumax,"O.K") -> O.K | E4: =IF(D4="O.K",0,1) -> 0
B5: Reinf - short - span | D5: =IF('Design of Slab'!C41="O.K","O.K") -> O.K | E5: =IF(D5="O.K",0,1) -> 0
B6: Reinf - short - support | D6: =IF('Design of Slab'!D41="O.K","O.K") -> O.K | E6: =IF(D6="O.K",0,1) -> 0
B7: Reinf-long-span | D7: =IF('Design of Slab'!E41="O.K","O.K") -> O.K | E7: =IF(D7="O.K",0,1) -> 0
B8: Reinf-long-support | D8: =IF('Design of Slab'!F41="O.K","O.K") -> O.K | E8: =IF(D8="O.K",0,1) -> 0
B9: Defflection ratio | D9: =IF('Design of Slab'!G46="O.K","O.K") -> O.K | E9: =IF(D9="O.K",0,1) -> 0
B10: Deflection value | D10: =IF('Design of Slab'!G47="O.K","O.K") -> O.K | E10: =IF(D10="O.K",0,1) -> 0
E11: =SUM(E3:E10) -> 0

Sheet ShearCheck
A1: Shear Check for Slab as IS 456 : 2000
A2: Effective depth in mm | D2: =d -> 120 | E2: mm
A3: Longer side of the panel = Ly = | D3: =Ly -> 4 | E3: m | I3: =Ly -> 4 | J3: m
A4: Shorter side of the panel = Lx = | D4: =+Lx -> 3 | E4: m
A5: Ultimate UDL = Wult= | D5: =Wult -> 24.975 | E5: Kn/m^2 | K5: =Lx -> 3 | L5: m
G6: Area = | H6: =1/2*Lx*Lx/2 -> 2.25
A7: Shear Force along the longer side of the panel
A8: Total Trapizoidal load = | D8: =I9*Wult -> 93.65625 | E8: Kn | P8: =IF(K8>Q3,">","<") -> < | Q8: =Q3 -> 0 | S8: N/mm2 | W8: (OK)
A9: Ultimate load / m run = | D9: =D8/Ly -> 23.414062 | E9: Kn/m | H9: Area= | I9: =(2*Ly*Lx-Lx^2)/4 -> 3.75 | J9: m^2
A11: Shear Force along the shorter side of the panel | F11: Design ult. shear force : Vu= | I11: =MAX(D9,D13) -> 23.414062 | J11: Kn
A12: Total Triangular load = | D12: =H6*Wult -> 56.19375 | E12: Kn
A13: Ultimate load / m run = | D13: =D12/Lx -> 18.73125 | E13: Kn/m | F13: Actual shear stress = | I13: =I11*1000/(deff_2*1000) -> 0.21285511 | J13: N/mm2
A15: Calculation of allowable shear stress
D16: Short Span | F16: Long Span
D17: at span | E17: at support | F17: at span | G17: at support
A18: Diameter of the bar = | D18: ='Design of Slab'!C36 -> 10 | E18: ='Design of Slab'!D36 -> 10 | F18: ='Design of Slab'!E36 -> 10 | G18: ='Design of Slab'!F36 -> 10
A19: Spacing of the bars in mm= | D19: ='Design of Slab'!C40 -> 175 | E19: ='Design of Slab'!D40 -> 175 | F19: ='Design of Slab'!E40 -> 175 | G19: ='Design of Slab'!F40 -> 175 | H19: Reqd. effec. Depth = | J19: =Vu*1000/(1000*D24) -> 41.120587
A20: Area of steel provided in mm^2= | D20: =PI()/4*D18^2*1000/D19 -> 448.79895 | E20: =PI()/4*E18^2*1000/E19 -> 448.79895 | F20: =PI()/4*F18^2*1000/F19 -> 448.79895 | G20: =PI()/4*G18^2*1000/G19 -> 448.79895 | H20: For solid slab other than flat slab, there is an increase of Tauc by K times as per Clause 40.2.1.1 of IS 456
A21: Percentage of reinforcement= | D21: =D20/(b*deff_1)*100 -> 0.37399913 | E21: =E20/(b*deff_2)*100 -> 0.40799905 | F21: =F20/(b*deff_3)*100 -> 0.40799905 | G21: =G20/(b*deff_4)*100 -> 0.40799905
A22: Respective pt for shear = | D22: =IF(Vu=D9,E21,G21) -> 0.40799905
A23: Grade of concrete, N/mm^2 | D23: =fck -> 25 | H23: K = | I23: =IF(T<=150,1.3,IF(T<=175,1.25,IF(T<=200,1.2,IF(T<=225,1.15, IF(T<=250,1.1,IF(T<=275,1.05,1)))))) -> 1.3
A24: Design shear strength of conc. | D24: =Tauc*K -> 0.5694 | H24: =IF(D24>=actualshearstress,"O.K","NOT O.K") -> O.K
A25: ="The design shear strength is"&IF(D24>=actualshearstress," more than"," less than")&" actual shear stress" -> The design shear strength is more than actual shear stress

Sheet Crackwidth
A1: CHECK FOR CRACK WIDTH
A3: Max moment acting on the element | D3: =MAX(Mu_sh_span,Mu_sh_supp,Mu_ln_span,Mu_ln_supp) -> 13.261725 | E3: kNm
A4: Instantaneous modulus of elasticity Ec = | D4: =Ec -> 25000 | E4: kN/mm2
A5: Modular Ratio m = | C5: Es | D5: =m -> 8
C6: Ec
A7: Ast = | B7: =MAX(1000*PI()/4*'Design of Slab'!C36^2/'Design of Slab'!C40,1000*PI()/4*'Design of Slab'!D36^2/'Design of Slab'!D40) -> 448.79895 | C7: mm2
A8: Asc = | B8: 0 | C8: mm2
A9: p = | B9: =pt_s_sp -> 0.37399913
A10: p' = | B10: 0
A11: The neutral axis is given by
A12: Hence x = | B12: [(m^2(p+1.5p')^2 +2*m*(p+1.5*p'*d'/d))^.5 -m*(p+1.5*p')]d | F12: (Taking compression steel into account)
A13: = | B13: =((m^2*(B9+1.5*B10)^2+2*m*(B9+1.5*B10*cover/d))^0.5-m*(B9+1.5*B10))*d -> 104.72642 | C13: mm.
A14: Icr = | B14: b*x^3/3 +(1.5*m-1)Asc(x-d')^2+mAst(d-x)^2
B15: = | C15: =(1000*B13^3/3+(1.5*D5-1)*B8*(B13-d)^2+D5*B7*(d-B13)^2) -> 3.8370425e+08 | D15: mm^3
A16: The stress in the reinforcement
B17: fs = | C17: =D5*D3*1000000/C15*(d-B13) -> 4.2231269 | D17: N/mm2
A18: Position | B18: y | C18: acr | D18: a1 | E18: e1 x10-3 | F18: e2 x10-3
A19: 1 | B19: =T-B13 -> 45.273576 | C19: =SQRT(('Design of Slab'!D11)^2+('Design of Slab'!D11)^2)-'Design of Slab'!C36/2 -> 30.355339 | D19: =T -> 150 | E19: =B19/(d-B13)*C17/200/1000*1000 -> 0.062590468 | F19: =1000*(T-B13)*(D19-B13)/3/200/B7/(d-B13) -> 0.49836299
A20: 2 | B20: =(d-B13)/2 -> 7.636788 | C20: =SQRT(B20^2+'Design of Slab'!D85)-'Design of Slab'!C36/2 -> 2.636788 | D20: =T-Crackwidth!B20 -> 142.36321 | E20: =B20/(d-B13)*C17/200/1000*1000 -> 0.010557817 | F20: =1000*(T-B13)*(B20-B13)/3/200/B7/(d-B13) -> -1.0687444
A21: Hence em = | B21: e1 x10-3 - | C21: e2 x10-3
B22: = | C22: =(E19-F19)/1000 -> -0.00043577252 | D22: mm. | E22: for position 1 | F22: =IF(C22<0,"NO CRACK FORMED","CALCULATION OF CRACK WIDTH REQUIRED") -> NO CRACK FORMED
B23: = | C23: =(E20-F20)/1000 -> 0.0010793022 | D23: mm. | E23: for position 2 | F23: =IF(C23<0,"NO CRACK FORMED","CALCULATION OF CRACK WIDTH REQUIRED") -> CALCULATION OF CRACK WIDTH REQUIRED
A24: Crack width = | B24: =3*C19*C22/(1+2*(C19-'Design of Slab'!D11)/(T-B13)) -> -0.032091875 | C24: mm. | D24: For position 1 | F24: =IF(B24<0.2,"SAFE","REVISE THE SECTION") -> SAFE
A25: Crack width = | B25: =3*C20*C23/(1+2*(C20-'Design of Slab'!D11)/(T-B13)) -> 0.70644154 | C25: mm. | D25: For position 2 | F25: =IF(B25<0.2,"SAFE","REVISE THE SECTION") -> REVISE THE SECTION

Sheet Actual deflection
A1: Deflection Check for Slab as per IS 456:2000 | T1: Coefficient for Deflection | U1: Coefficient for ShrinkageDeflection
T2: Deflection=coeff x wl^4/EI | U2: Deflection=coeff x l^2x shrinkage coeff
A4: Total Deflection = Short term Deflection + Long Term Deflection | P4: All edges discontinuous | S4: Cond-1 | T4: =5/384 -> 0.013020833 | U4: 0.125
P5: All edges continuous | S5: Cond-2 | T5: =1/384 -> 0.0026041667 | U5: 0.0625
A6: Equivalent uniform distributed load | P6: Two long edges discontinuous | S6: Cond-3 | T6: =T4 -> 0.013020833 | U6: 0.125
A7: Unfactored Total reaction of shorter span = | E7: =ShearCheck!D9/1.5 -> 15.609375 | F7: Kn/m | P7: Two short edges discontinuous | S7: Cond-4 | T7: =T5 -> 0.0026041667 | U7: =U5 -> 0.0625
A8: Unfactored UDL (DL+LL) | E8: =E7*2/Lx -> 10.40625 | F8: Kn/m | P8: Two adjacent edges discontinuous | S8: Cond-5 | T8: =1/185 -> 0.0054054054 | U8: 0.086
A9: Unfactored UDL for Dead Load = | E9: =E8/(DL+LL)*DL -> 7.28125 | F9: Kn/m
A11: Short Term Deflection | D11: δc | M11: Calculation of Ig
A12: Elastic Deflection calculated by usual Methods using Ec and Ie | H12: Calculation of Ie | M12: Total depth = | O12: =T -> 150 | P12: Only one long edge discontinuous | S12: Cond-6 | T12: =1/185 -> 0.0054054054 | U12: =U8 -> 0.086
H13: Modular Ratio m | K13: =m -> 8 | M13: Area of Steel Ast= | O13: =ShearCheck!D20 -> 448.79895
A14: Short Term Modulus of Elasticity of Concrete Ec | F14: =Ec -> 25000 | G14: N/mm2 | H14: Reinforcement Percentage p | K14: =pt_s_sp -> 0.37399913 | M14: Yt from top in mm= | O14: =(b*O12*O12/2+(m-1)*O13*d)/(b*T+O13) -> 77.282047 | P14: Only one short edge discontinuous | S14: Cond-7 | T14: =1/384 -> 0.0026041667 | U14: =U5 -> 0.0625
A15: Effective Moment of Inertia Ie | E15: =IF(Ig>Icr, IF(Ie<Icr,Icr,IF(Ie>Ig,Ig)),IF(Ie>Ig,Ig,Ie)) -> 2.8776401e+08 | G15: mm4 | H15: Neutral Axis from Top x | K15: =Crackwidth!B13 -> 104.72642 | L15: mm | M15: 1/12*b*T^3= | O15: =1/12*b*T^3 -> 281250000
H16: M.O.I. of Cracked Section Icr | K16: =b*K15^3/3+m*ShearCheck!D20*(d-'Actual deflection'!K15)^2 -> 3.8370425e+08 | L16: mm4 | M16: b*d*(Yt-T/2)^2 | O16: =b*T*(O14-T/2)^2 -> 781160.63 | P16: Only one short edge continuous | S16: Cond-8 | T16: =5/384 -> 0.013020833 | U16: =U4 -> 0.125
A17: End Conditions of Slab | H17: M.O.I. of Uncracked Section Ig | K17: =O18 -> 2.8776401e+08 | L17: mm4 | M17: (m-1)*Ast*(d-Yt)^2 | O17: =(m-1)*O13*(d-O14)^2 -> 5732852.2
A18: ='Design of Slab'!G20 -> Two short edges discontinuous | H18: Modulus of Rupture fcr | K18: =0.7*fck^0.5 -> 3.5 | L18: N/mm2 | O18: =O15+O16+O17 -> 2.8776401e+08 | P18: Only one long edge continuous | S18: Cond-9 | T18: =1/185 -> 0.0054054054 | U18: =U8 -> 0.086
H19: Distance of extreme Tension fibre from
A20: Hence | H20: centroid of Section Yt | K20: =T/2 -> 75 | L20: mm
A21: Short Term Deflection | D21: δc | E21: =T22*E8*(Lx*1000)^4/F14/E15 -> 0.30512062 | F21: mm | H21: Cracking Moment of Section Mcr | K21: =K18*K17/K20 -> 13428987 | L21: Nmm | P21: Support index of the slab under design = | T21: =Condition -> Cond-4 | U21: =Condition -> Cond-4
H22: Maximum Moment M | K22: =Mu_sh_span*1000000 -> 9890100 | L22: Nmm | P22: Coefficient for elastic deflection | T22: =VLOOKUP(T21,S4:T19,2) -> 0.0026041667 | U22: =VLOOKUP(U21,S4:U19,3) -> 0.0625
H23: Lever Arm Z | K23: ='Design of Slab'!J21-K15/3 -> 85.091192 | L23: mm
H24: Ie | K24: =K16/MAX(0.1,(1.2-K21/K22*K23/d*(1-K15/d)*1)) -> 3.5612182e+08 | L24: mm4
P25: Values for k3
A26: Long Term Deflection | D26: δe | P26: All edges discontinuous | S26: Cond-1 | T26: =U4 -> 0.125
A27: Deflection due to Shrinkage and Creep | P27: All edges continuous | S27: Cond-2 | T27: =U5 -> 0.0625
H28: pt-pc | K28: =K14-0 -> 0.37399913 | P28: Two long edges discontinuous | S28: Cond-3 | T28: =U6 -> 0.125
A29: Deflection due to Shrinkage | D29: acs | E29: =K33 -> 0.49535929 | F29: mm | H29: k3 | K29: =T44 -> 0.0625 | P29: Two short edges discontinuous | S29: Cond-4 | T29: =U7 -> 0.0625
A30: Refer to Annexure-C | H30: k4 | K30: =MIN(1,IF(K28<0.25,0.5,IF(K28<1,0.72*K14^0.5,0.65*K14^0.5))) -> 0.44031937 | P30: Two adjacent edges discontinuous | S30: Cond-5 | T30: =U8 -> 0.086
H31: εcs | K31: 0.0003
H32: ψcs | K32: =K30*K31/T -> 8.8063874e-07
H33: acs | K33: =K29*K32*(Lx*1000)^2 -> 0.49535929 | L33: mm
P34: Only one long edge discontinuous | S34: Cond-6 | T34: =U12 -> 0.086
A35: Deflection due to Creep | D35: acc(perm) | E35: = | F35: ai,cc(perm) - ai(perm)
P36: Only one short edge discontinuous | S36: Cond-7 | T36: =U14 -> 0.0625
A37: ai,cc(perm)
A38: Initial plus Creep Deflection due to Permanent loads obtained using an Elastic Analysis with an effective Modulus of Elasticity. | P38: Only one short edge continuous | S38: Cond-8 | T38: =U16 -> 0.125
A39: θ | B39: 1.6
A40: Ece | B40: =Ec/(1+B39) -> 9615.3846 | C40: N/mm2 | P40: Only one long edge continuous | S40: Cond-9 | T40: =U18 -> 0.086
A41: ai,cc(perm) | B41: =E21/E8*E9*F14/B40 -> 0.5550813 | C41: mm
A43: ai(perm) | P43: Support index of the slab under design = | T43: =Condition -> Cond-4
...

Sheet Deflection control
A1: Deflection Control
A2: {Reference : Clause 23,23.2.1, 24.1, 42.1, Annexure-C and Chapter-5 of "Reinforced Concrete Design" By S.N.Sinha }
A3: Longer span : Ly | D3: =Ly -> 4 | E3: m
A4: Shorter span :Lx | D4: =Lx -> 3 | E4: m
A5: Span Ratio | D5: =ratio -> 1.3333333
A6: Support condition | D6: =Condition -> Cond-4
A7: This is a | D7: =IF(ratio>2,1,2) -> 2 | E7: way slab
A9: Deflection for two way slab
D10: Allowable | E10: Modified Value | G10: required | H10: Applicable
D11: Span / depth | E11: for Fe 415 | F11: for stress | G11: deff | H11: for
A12: Simply Supported slab | D12: 23 | E12: 23 | F12: =E12*MF -> 46 | G12: =Lx*1000/F12 -> 65.217391 | H12: all other
A13: Continuous slab | D13: 23 | E13: 23 | F13: =E13*MF -> 46 | G13: =Lx*1000/F13 -> 65.217391 | H13: Cond-2
A14: Above allowable ratio to be modified as per reinforcent of slab
E24: Short Span | G24: Long Span
E25: at span | F25: at support | G25: at span | H25: at support
A26: Area of steel required | E26: =Ast_sh_span -> 195.90266 | F26: =Ast_sh_supp -> 268.43351 | G26: =Ast_ln_span -> 155.54074 | H26: =Ast_ln_supp -> 0
A27: Diameter of bar provided | E27: ='Design of Slab'!C36 -> 10 | F27: ='Design of Slab'!D36 -> 10 | G27: ='Design of Slab'!E36 -> 10 | H27: ='Design of Slab'!F36 -> 10
A28: Spacing provided | E28: ='Design of Slab'!C40 -> 175 | F28: ='Design of Slab'!D40 -> 175 | G28: ='Design of Slab'!E40 -> 175 | H28: ='Design of Slab'!F40 -> 175
A29: Area of steel provided | E29: =(PI()/4*E27^2*1000/E28) -> 448.79895 | F29: =(PI()/4*F27^2*1000/F28) -> 448.79895 | G29: =(PI()/4*G27^2*1000/G28) -> 448.79895 | H29: =(PI()/4*H27^2*1000/H28) -> 448.79895
A30: Ratio of Ast(reqd) / Ast(provided) | E30: =E26/E29 -> 0.43650428 | F30: =F26/F29 -> 0.59811527 | G30: =G26/G29 -> 0.34657109 | H30: =H26/H29 -> 0
A31: Design Ratio = (for mid span in shorter direction) | E31: =E30 -> 0.43650428
A32: Stress in steel fs = 0.58fy x ratio (N/mm^2) | E32: =0.58*fy*E31 -> 126.58624
A33: Maximum Span reinforcement | E33: =E29 -> 448.79895
A34: Modification Factor = MF | E34: =MAX(MIN(1/(0.225+0.00322*fs-0.625*LOG10(b*d/(100*Ast))),2),0.65) -> 2
A36: Applicable for this slab | E36: =IF(Condition="Cond-2",F13,F12) -> 46
A37: Eff depth reqd from deflection point of view | E37: =Lx*1000/E36 -> 65.217391
A38: Overall depth required | E38: =E37+(T-d) -> 95.217391

Sheet Backup cal for Mul & Xul
A1: SUPPORTING CALCULATION
A3: Maximum Moment = | D3: =MAX(Mu_sh_span, Mu_sh_supp, Mu_ln_span,Mu_ln_supp) -> 13.261725 | E3: Kn-m
A4: Width of the section = | D4: 1000 | E4: mm
A5: Depth of the section = | D5: =T -> 150 | E5: mm
A6: Clear cover to main reinf. = | D6: =cover -> 25 | E6: mm
A7: Elastic Modulus of steel = Es= | D7: =Es -> 200000 | E7: N/mm2
A8: Grade of Steel = fy= | D8: =fy -> 500 | E8: N/mm2
A9: Grade of Concrete= fck= | D9: =fck -> 25 | E9: N/mm2
A11: Calculation of Ultimate moment of resistance of the singly reinforced balanced section
A13: Mul= 0.36 x fck x b x Xul x (d-0.416. Xul)
A14: In case of balanced section= Mu/bd^2= | E14: =0.36*fck*xul_coeff*(1-0.416*xul_coeff) -> 3.3256332 | F14: as Xul/d = | G14: =xul_coeff -> 0.45602606
A15: Effective depth required (d1) | E15: =SQRT(Mumax*1000000/(E14*b)) -> 63.148471 | F15: mm | G15: (from flexure)
A16: Allowable span to effective depth ratio | E16: =(IF(Condition="cond-2",'Deflection control'!E13,'Deflection control'!E12))*1.5 -> 34.5 | F16: (as starting assume modification factor as 1.5)
A17: Effective depth required (d2) | E17: =Lx*1000/E16 -> 86.956522 | F17: mm | G17: (from deflection)
A18: Effective depth required (d3) | E18: =ShearCheck!J19 -> 41.120587 | F18: mm | G18: (from shear)
A19: Overall depth required | E19: =MAX(E15,E17,E18)+(cover+5) -> 116.95652 | F19: mm
A20: Effective depth of the section= | D20: =deff_1 -> 120 | E20: mm | F20: (Actual)
A22: Computation of depth of neutral axis for balanced section = Xul | I22: strain of concrete = 0.0035
H28: strain of steel = 0.002+fy/Es
H29: STRAIN DIAGRAM
C30: = | D30: =(0.0035/(0.0055+0.87*fy/Es)) -> 0.45602606 | E30: x d
C31: = | D31: =xul_coeff*deff -> 54.723127 | E31: mm
A33: Mul = | B33: =0.36*fck*b*xul*(d-0.416*xul)/1000000 -> 47.889118 | C33: Kn-m
A34: Remarks:- | B34: =IF(Mul=Mumax,"It has been designed as balanced section",IF(Mul>Mumax," It has been designed as under-reinforced section", IF(Mul< Mumax, " It is becoming over-reinforced section, so increase the depth"))) -> It has been designed as under-reinforced section
A35: Decision :- | B35: =IF(Mul>=Mumax,"Y", "N") -> Y
F36: Short Span | H36: Long Span
F37: at span | G37: at support | H37: at span | I37: at support
C38: Diameter proposed by Designer | F38: ='Design of Slab'!C36 -> 10 | G38: ='Design of Slab'!D36 -> 10 | H38: ='Design of Slab'!E36 -> 10 | I38: ='Design of Slab'!F36 -> 10
C39: Default diameter | F39: 10 | G39: 10 | H39: 10 | I39: 10
C40: Diameter consudered for cal | F40: =IF(F38>0,F38,F39) -> 10 | G40: =IF(G38>0,G38,G39) -> 10 | H40: =IF(H38>0,H38,H39) -> 10 | I40: =IF(I38>0,I38,I39) -> 10
C41: Effective depth in mm | F41: =T-cover-F40/2 -> 120 | G41: =T-cover-G40/2-G40 -> 110 | H41: =T-cover-F40-H40/2 -> 110 | I41: =T-cover-I40/2-I40 -> 110
A42: Ultimate Moments in Kn-m | F42: =Mu_sh_span -> 9.8901 | G42: =Mu_sh_supp -> 13.261725 | H42: =Mu_ln_span -> 7.867125 | I42: =Mu_ln_supp -> 0
A43: Calculation of neutral axis = Xu
A44: Sqrt(1.4446-6.67735x Mu/(fck b d^2)) | F44: =SQRT(1.4446-6.67735*F42*1000000/(fck*b*deff_1^2)) -> 1.1230122 | G44: =SQRT(1.4446-6.67735*G42*1000000/(fck*b*deff_2^2)) -> 1.0732484 | H44: =SQRT(1.4446-6.67735*H42*1000000/(fck*b*deff_3^2)) -> 1.1273606 | I44: =SQRT(1.4446-6.67735*I42*1000000/(fck*b*deff_4^2)) -> 1.2019151
A45: 1.202+Sqrt(1.4446-6.67735x Mu/(fck b d^2)) | F45: =1.202+F44 -> 2.3250122 | G45: =1.202+G44 -> 2.2752484 | H45: =1.202+H44 -> 2.3293606 | I45: =1.202+I44 -> 2.4039151
A46: 1.202-Sqrt(1.4446-6.67735x Mu/(fck b d^2)) | F46: =1.202-F44 -> 0.078987755 | G46: =1.202-G44 -> 0.12875156 | H46: =1.202-H44 -> 0.074639369 | I46: =1.202-I44 -> 8.4861565e-05
A47: Xu/d = | F47: =MIN(F45,F46) -> 0.078987755 | G47: =MIN(G45,G46) -> 0.12875156 | H47: =MIN(H45,H46) -> 0.074639369 | I47: =MIN(I45,I46) -> 8.4861565e-05
A48: Xu= | F48: =F47*d -> 9.4785306 | G48: =G47*d -> 15.450187 | H48: =H47*d -> 8.9567242 | I48: =I47*d -> 0.010183388
A49: Ast= | F49: =IF(Check="Y",F42*1000000/(0.87*fy*(d-0.416*F48)),"Remarks") -> 195.90266 | G49: =IF(Check="Y",G42*1000000/(0.87*fy*(d-0.416*G48)),"Remarks") -> 268.43351 | H49: =IF(Check="Y",H42*1000000/(0.87*fy*(d-0.416*H48)),"Remarks") -> 155.54074 | I49: =IF(Check="Y",I42*1000000/(0.87*fy*(d-0.416*I48)),"Remarks") -> 0
A51: Note:- In the rest of this program the Xu has been defined as lever arm of section at the middle of short span

Sheet Moment Coeff
A1: Bending Moment Coefficients Calculation as per IS 456- 2000 for rectangular panels
A2: Ratio (Ly/Lx) of the panel to be designed | C2: ='Design of Slab'!J13 -> 1.3333333
A3: Ratio reference number for picking up the co-eff= | C3: =CEILING((C2-1)*10,1) -> 4 | F3: Short Span Coeff | H3: Long Span Coeff
A4: Support Condition | C4: ='Design of Slab'!G19 -> Cond-4 | F4: span (+ve) moment | G4: supp't (-ve) moment | H4: span (+ve) moment | I4: supp't (-ve) moment
D5: Coefficients are:- | F5: =IF(C2<=2,VLOOKUP(C4,B12:O27,C3+2),VLOOKUP(C4,B12:P27,15)) -> 0.044 | G5: =IF(C2<=2,VLOOKUP(C4,B34:O49,C3+2),VLOOKUP(C4,B34:P49,15)) -> 0.059 | H5: =IF(C2<=2,VLOOKUP(C4,B12:O27,14),0) -> 0.035 | I5: =IF(C2<=2,VLOOKUP(C4,B34:O49,14),0) -> 0
A7: {REFERENCE : Clauses 24.4 & 37.1.2 and Annexure-D of IS 456:2000}
A9: Positive Moment Coefficients at Mid Span | P9: For one way slab
C10: Ratio (Ly/Lx) reference number calculated as (ratio - 1)x10 for short span co-eff and 11 for long span coeff.
C11: 0 | D11: 1 | E11: 2 | F11: 3 | G11: 4 | H11: 5 | I11: 6 | J11: 7 | K11: 7.5 | L11: 8 | M11: 9 | N11: 10 | O11: 11 | P11: 12
A12: ='Support Index'!B7 -> All edges discontinuous | B12: Cond-1 | C12: 0.056 | D12: 0.064 | E12: 0.072 | F12: 0.079 | G12: 0.085 | H12: 0.089 | I12: =(K12-H12)/2.5*1+H12 -> 0.0934 | J12: =(K12-H12)/2.5*2+H12 -> 0.0978 | K12: 0.1 | L12: =(N12-K12)/2.5*0.5+K12 -> 0.1014 | M12: =(N12-K12)/2.5*1.5+K12 -> 0.1042 | N12: 0.107 | O12: 0.056 | P12: 0.125
A13: ='Support Index'!B8 -> All edges continuous | B13: Cond-2 | C13: 0.024 | D13: 0.028 | E13: 0.032 | F13: 0.036 | G13: 0.039 | H13: 0.041 | I13: =(K13-H13)/2.5*1+H13 -> 0.0426 | J13: =(K13-H13)/2.5*2+H13 -> 0.0442 | K13: 0.045 | L13: =(N13-K13)/2.5*0.5+K13 -> 0.0458 | M13: =(N13-K13)/2.5*1.5+K13 -> 0.0474 | N13: 0.049 | O13: 0.024 | P13: 0.083
A14: ='Support Index'!B9 -> Two long edges discontinuous | B14: Cond-3 | C14: 0.035 | D14: 0.043 | E14: 0.051 | F14: 0.057 | G14: 0.063 | H14: 0.068 | I14: =(K14-H14)/2.5*1+H14 -> 0.0728 | J14: =(K14-H14)/2.5*2+H14 -> 0.0776 | K14: 0.08 | L14: =(N14-K14)/2.5*0.5+K14 -> 0.0816 | M14: =(N14-K14)/2.5*1.5+K14 -> 0.0848 | N14: 0.088 | O14: 0.035 | P14: 0.125
A15: ='Support Index'!B10 -> Two short edges discontinuous | B15: Cond-4 | C15: 0.035 | D15: 0.037 | E15: 0.04 | F15: 0.043 | G15: 0.044 | H15: 0.045 | I15: =(K15-H15)/2.5*1+H15 -> 0.0466 | J15: =(K15-H15)/2.5*2+H15 -> 0.0482 | K15: 0.049 | L15: =(N15-K15)/2.5*0.5+K15 -> 0.0496 | M15: =(N15-K15)/2.5*1.5+K15 -> 0.0508 | N15: 0.052 | O15: 0.035 | P15: 0.083
A16: ='Support Index'!B11 -> Two adjacent edges discontinuous | B16: Cond-5 | C16: 0.035 | D16: 0.04 | E16: 0.045 | F16: 0.049 | G16: 0.053 | H16: 0.056 | I16: =(K16-H16)/2.5*1+H16 -> 0.0588 | J16: =(K16-H16)/2.5*2+H16 -> 0.0616 | K16: 0.063 | L16: =(N16-K16)/2.5*0.5+K16 -> 0.0642 | M16: =(N16-K16)/2.5*1.5+K16 -> 0.0666 | N16: 0.069 | O16: 0.035 | P16: 0.1
A20: ='Support Index'!B15 -> Only one long edge discontinuous | B20: Cond-6 | C20: 0.028 | D20: 0.033 | E20: 0.039 | F20: 0.044 | G20: 0.047 | H20: 0.051 | I20: =(K20-H20)/2.5*1+H20 -> 0.0542 | J20: =(K20-H20)/2.5*2+H20 -> 0.0574 | K20: 0.059 | L20: =(N20-K20)/2.5*0.5+K20 -> 0.0602 | M20: =(N20-K20)/2.5*1.5+K20 -> 0.0626 | N20: 0.065 | O20: 0.028 | P20: 0.1
A22: ='Support Index'!B17 -> Only one short edge discontinuous | B22: Cond-7 | C22: 0.028 | D22: 0.032 | E22: 0.036 | F22: 0.039 | G22: 0.041 | H22: 0.044 | I22: =(K22-H22)/2.5*1+H22 -> 0.0456 | J22: =(K22-H22)/2.5*2+H22 -> 0.0472 | K22: 0.048 | L22: =(N22-K22)/2.5*0.5+K22 -> 0.0488 | M22: =(N22-K22)/2.5*1.5+K22 -> 0.0504 | N22: 0.052 | O22: 0.028 | P22: 0.083
A24: ='Support Index'!B21 -> Only one short edge continuous | B24: Cond-8 | C24: 0.043 | D24: 0.051 | E24: 0.059 | F24: 0.065 | G24: 0.071 | H24: 0.076 | I24: =(K24-H24)/2.5*1+H24 -> 0.0804 | J24: =(K24-H24)/2.5*2+H24 -> 0.0848 | K24: 0.087 | L24: =(N24-K24)/2.5*0.5+K24 -> 0.0888 | M24: =(N24-K24)/2.5*1.5+K24 -> 0.0924 | N24: 0.096 | O24: 0.043 | P24: 0.125
A26: ='Support Index'!B23 -> Only one long edge continuous | B26: Cond-9 | C26: 0.043 | D26: 0.048 | E26: 0.053 | F26: 0.057 | G26: 0.06 | H26: 0.064 | I26: =(K26-H26)/2.5*1+H26 -> 0.066 | J26: =(K26-H26)/2.5*2+H26 -> 0.068 | K26: 0.069 | L26: =(N26-K26)/2.5*0.5+K26 -> 0.0698 | M26: =(N26-K26)/2.5*1.5+K26 -> 0.0714 | N26: 0.073 | O26: 0.043 | P26: 0.1
C29: Note :For one way slab the co-efficients have been taken from Table-12 IS 456:2000, for live load as conservative approach.
A31: Negative Moment Coefficients at Continuous Support | P31: For one way slab
C32: Ratio (Ly/Lx) reference number calculated as (ratio - 1)x10 for short span co-eff and 11 for long span coeff.
C33: 0 | D33: 1 | E33: 2 | F33: 3 | G33: 4 | H33: 5 | I33: 6 | J33: 7 | K33: 7.5 | L33: 8 | M33: 9 | N33: 10 | O33: 11 | P33: 12
A34: =A12 -> All edges discontinuous | B34: Cond-1 | C34: 0 | D34: 0 | E34: 0 | F34: 0 | G34: 0 | H34: 0 | I34: =(K34-H34)/2.5*1+H34 -> 0 | J34: =(K34-H34)/2.5*2+H34 -> 0 | K34: 0 | L34: =(N34-K34)/2.5*0.5+K34 -> 0 | M34: =(N34-K34)/2.5*1.5+K34 -> 0 | N34: 0 | O34: 0 | P34: 0
A35: =A13 -> All edges continuous | B35: Cond-2 | C35: 0.032 | D35: 0.037 | E35: 0.043 | F35: 0.047 | G35: 0.051 | H35: 0.053 | I35: =(K35-H35)/2.5*1+H35 -> 0.0558 | J35: =(K35-H35)/2.5*2+H35 -> 0.0586 | K35: 0.06 | L35: =(N35-K35)/2.5*0.5+K35 -> 0.061 | M35: =(N35-K35)/2.5*1.5+K35 -> 0.063 | N35: 0.065 | O35: 0.032 | P35: 0.11
A36: =A14 -> Two long edges discontinuous | B36: Cond-3 | C36: 0 | D36: 0 | E36: 0 | F36: 0 | G36: 0 | H36: 0 | I36: =(K36-H36)/2.5*1+H36 -> 0 | J36: =(K36-H36)/2.5*2+H36 -> 0 | K36: 0 | L36: =(N36-K36)/2.5*0.5+K36 -> 0 | M36: =(N36-K36)/2.5*1.5+K36 -> 0 | N36: 0 | O36: 0.045 | P36: 0
A37: =A15 -> Two short edges discontinuous | B37: Cond-4 | C37: 0.045 | D37: 0.049 | E37: 0.052 | F37: 0.056 | G37: 0.059 | H37: 0.06 | I37: =(K37-H37)/2.5*1+H37 -> 0.062 | J37: =(K37-H37)/2.5*2+H37 -> 0.064 | K37: 0.065 | L37: =(N37-K37)/2.5*0.5+K37 -> 0.0658 | M37: =(N37-K37)/2.5*1.5+K37 -> 0.0674 | N37: 0.069 | O37: 0 | P37: 0.11
A38: =A16 -> Two adjacent edges discontinuous | B38: Cond-5 | C38: 0.047 | D38: 0.053 | E38: 0.06 | F38: 0.065 | G38: 0.071 | H38: 0.075 | I38: =(K38-H38)/2.5*1+H38 -> 0.0786 | J38: =(K38-H38)/2.5*2+H38 -> 0.0822 | K38: 0.084 | L38: =(N38-K38)/2.5*0.5+K38 -> 0.0854 | M38: =(N38-K38)/2.5*1.5+K38 -> 0.0882 | N38: 0.091 | O38: 0.047 | P38: 0.11
A42: =A20 -> Only one long edge discontinuous | B42: Cond-6 | C42: 0.037 | D42: 0.044 | E42: 0.052 | F42: 0.057 | G42: 0.063 | H42: 0.067 | I42: =(K42-H42)/2.5*1+H42 -> 0.071 | J42: =(K42-H42)/2.5*2+H42 -> 0.075 | K42: 0.077 | L42: =(N42-K42)/2.5*0.5+K42 -> 0.0786 | M42: =(N42-K42)/2.5*1.5+K42 -> 0.0818 | N42: 0.085 | O42: 0.037 | P42: 0.11
A44: =A22 -> Only one short edge discontinuous | B44: Cond-7 | C44: 0.037 | D44: 0.043 | E44: 0.048 | F44: 0.051 | G44: 0.055 | H44: 0.057 | I44: =(K44-H44)/2.5*1+H44 -> 0.0598 | J44: =(K44-H44)/2.5*2+H44 -> 0.0626 | K44: 0.064 | L44: =(N44-K44)/2.5*0.5+K44 -> 0.0648 | M44: =(N44-K44)/2.5*1.5+K44 -> 0.0664 | N44: 0.068 | O44: 0.037 | P44: 0.11
A46: =A24 -> Only one short edge continuous | B46: Cond-8 | C46: 0 | D46: 0 | E46: 0 | F46: 0 | G46: 0 | H46: 0 | I46: =(K46-H46)/2.5*1+H46 -> 0 | J46: =(K46-H46)/2.5*2+H46 -> 0 | K46: 0 | L46: =(N46-K46)/2.5*0.5+K46 -> 0 | M46: =(N46-K46)/2.5*1.5+K46 -> 0 | N46: 0 | O46: 0.057 | P46: 0
A48: =A26 -> Only one long edge continuous | B48: Cond-9 | C48: 0.057 | D48: 0.064 | E48: 0.071 | F48: 0.076 | G48: 0.08 | H48: 0.084 | I48: =(K48-H48)/2.5*1+H48 -> 0.0868 | J48: =(K48-H48)/2.5*2+H48 -> 0.0896 | K48: 0.091 | L48: =(N48-K48)/2.5*0.5+K48 -> 0.0922 | M48: =(N48-K48)/2.5*1.5+K48 -> 0.0946 | N48: 0.097 | O48: 0 | P48: 0.11

Sheet Table-19
B1: TABLE-19
C2: Grade of Concrete
B3: % | C3: 15 | D3: 20 | E3: 25 | F3: 30 | G3: 35 | H3: 40
C4: ta (N/mm2)
C5: 1 | D5: 2 | E5: 3 | F5: 4 | G5: 5 | H5: 6
B6: 0.15 | C6: 0.28 | D6: 0.28 | E6: 0.29 | F6: 0.29 | G6: 0.29 | H6: 0.3 | I6: Grade of Concrete | K6: =fck -> 25
B7: =B6+0.01 -> 0.16 | C7: =C$6+(C$16-C$6)*($B7-$B$6)/($B$16-$B$6) -> 0.287 | D7: =D$6+(D$16-D$6)*($B7-$B$6)/($B$16-$B$6) -> 0.288 | E7: =E$6+(E$16-E$6)*($B7-$B$6)/($B$16-$B$6) -> 0.297 | F7: =F$6+(F$16-F$6)*($B7-$B$6)/($B$16-$B$6) -> 0.298 | G7: =G$6+(G$16-G$6)*($B7-$B$6)/($B$16-$B$6) -> 0.298 | H7: =H$6+(H$16-H$6)*($B7-$B$6)/($B$16-$B$6) -> 0.308 | I7: Grade reference | K7: =IF(fck=15,1,IF(fck=20,2,IF(fck=25,3,IF(fck=30,4,IF(fck=35,5,IF(fck=40,6,6)))))) -> 3
B8: =B7+0.01 -> 0.17 | C8: =C$6+(C$16-C$6)*($B8-$B$6)/($B$16-$B$6) -> 0.294 | D8: =D$6+(D$16-D$6)*($B8-$B$6)/($B$16-$B$6) -> 0.296 | E8: =E$6+(E$16-E$6)*($B8-$B$6)/($B$16-$B$6) -> 0.304 | F8: =F$6+(F$16-F$6)*($B8-$B$6)/($B$16-$B$6) -> 0.306 | G8: =G$6+(G$16-G$6)*($B8-$B$6)/($B$16-$B$6) -> 0.306 | H8: =H$6+(H$16-H$6)*($B8-$B$6)/($B$16-$B$6) -> 0.316 | I8: Reinf. Percentage | K8: =IF(shearpt<0.15,0.15,shearpt) -> 0.40799905
B9: =B8+0.01 -> 0.18 | C9: =C$6+(C$16-C$6)*($B9-$B$6)/($B$16-$B$6) -> 0.301 | D9: =D$6+(D$16-D$6)*($B9-$B$6)/($B$16-$B$6) -> 0.304 | E9: =E$6+(E$16-E$6)*($B9-$B$6)/($B$16-$B$6) -> 0.311 | F9: =F$6+(F$16-F$6)*($B9-$B$6)/($B$16-$B$6) -> 0.314 | G9: =G$6+(G$16-G$6)*($B9-$B$6)/($B$16-$B$6) -> 0.314 | H9: =H$6+(H$16-H$6)*($B9-$B$6)/($B$16-$B$6) -> 0.324 | I9: Allowable stress | K9: =VLOOKUP(K8,B6:H291,K7+1) -> 0.438
B10: =B9+0.01 -> 0.19 | C10: =C$6+(C$16-C$6)*($B10-$B$6)/($B$16-$B$6) -> 0.308 | D10: =D$6+(D$16-D$6)*($B10-$B$6)/($B$16-$B$6) -> 0.312 | E10: =E$6+(E$16-E$6)*($B10-$B$6)/($B$16-$B$6) -> 0.318 | F10: =F$6+(F$16-F$6)*($B10-$B$6)/($B$16-$B$6) -> 0.322 | G10: =G$6+(G$16-G$6)*($B10-$B$6)/($B$16-$B$6) -> 0.322 | H10: =H$6+(H$16-H$6)*($B10-$B$6)/($B$16-$B$6) -> 0.332
B11: =B10+0.01 -> 0.2 | C11: =C$6+(C$16-C$6)*($B11-$B$6)/($B$16-$B$6) -> 0.315 | D11: =D$6+(D$16-D$6)*($B11-$B$6)/($B$16-$B$6) -> 0.32 | E11: =E$6+(E$16-E$6)*($B11-$B$6)/($B$16-$B$6) -> 0.325 | F11: =F$6+(F$16-F$6)*($B11-$B$6)/($B$16-$B$6) -> 0.33 | G11: =G$6+(G$16-G$6)*($B11-$B$6)/($B$16-$B$6) -> 0.33 | H11: =H$6+(H$16-H$6)*($B11-$B$6)/($B$16-$B$6) -> 0.34
B12: =B11+0.01 -> 0.21 | C12: =C$6+(C$16-C$6)*($B12-$B$6)/($B$16-$B$6) -> 0.322 | D12: =D$6+(D$16-D$6)*($B12-$B$6)/($B$16-$B$6) -> 0.328 | E12: =E$6+(E$16-E$6)*($B12-$B$6)/($B$16-$B$6) -> 0.332 | F12: =F$6+(F$16-F$6)*($B12-$B$6)/($B$16-$B$6) -> 0.338 | G12: =G$6+(G$16-G$6)*($B12-$B$6)/($B$16-$B$6) -> 0.338 | H12: =H$6+(H$16-H$6)*($B12-$B$6)/($B$16-$B$6) -> 0.348
B13: =B12+0.01 -> 0.22 | C13: =C$6+(C$16-C$6)*($B13-$B$6)/($B$16-$B$6) -> 0.329 | D13: =D$6+(D$16-D$6)*($B13-$B$6)/($B$16-$B$6) -> 0.336 | E13: =E$6+(E$16-E$6)*($B13-$B$6)/($B$16-$B$6) -> 0.339 | F13: =F$6+(F$16-F$6)*($B13-$B$6)/($B$16-$B$6) -> 0.346 | G13: =G$6+(G$16-G$6)*($B13-$B$6)/($B$16-$B$6) -> 0.346 | H13: =H$6+(H$16-H$6)*($B13-$B$6)/($B$16-$B$6) -> 0.356
B14: =B13+0.01 -> 0.23 | C14: =C$6+(C$16-C$6)*($B14-$B$6)/($B$16-$B$6) -> 0.336 | D14: =D$6+(D$16-D$6)*($B14-$B$6)/($B$16-$B$6) -> 0.344 | E14: =E$6+(E$16-E$6)*($B14-$B$6)/($B$16-$B$6) -> 0.346 | F14: =F$6+(F$16-F$6)*($B14-$B$6)/($B$16-$B$6) -> 0.354 | G14: =G$6+(G$16-G$6)*($B14-$B$6)/($B$16-$B$6) -> 0.354 | H14: =H$6+(H$16-H$6)*($B14-$B$6)/($B$16-$B$6) -> 0.364
B15: =B14+0.01 -> 0.24 | C15: =C$6+(C$16-C$6)*($B15-$B$6)/($B$16-$B$6) -> 0.343 | D15: =D$6+(D$16-D$6)*($B15-$B$6)/($B$16-$B$6) -> 0.352 | E15: =E$6+(E$16-E$6)*($B15-$B$6)/($B$16-$B$6) -> 0.353 | F15: =F$6+(F$16-F$6)*($B15-$B$6)/($B$16-$B$6) -> 0.362 | G15: =G$6+(G$16-G$6)*($B15-$B$6)/($B$16-$B$6) -> 0.362 | H15: =H$6+(H$16-H$6)*($B15-$B$6)/($B$16-$B$6) -> 0.372
B16: =B15+0.01 -> 0.25 | C16: 0.35 | D16: 0.36 | E16: 0.36 | F16: 0.37 | G16: 0.37 | H16: 0.38
B17: =B16+0.01 -> 0.26 | C17: =C$16+(C$41-C$16)*($B17-$B$16)/($B$41-$B$16) -> 0.3544 | D17: =D$16+(D$41-D$16)*($B17-$B$16)/($B$41-$B$16) -> 0.3648 | E17: =E$16+(E$41-E$16)*($B17-$B$16)/($B$41-$B$16) -> 0.3652 | F17: =F$16+(F$41-F$16)*($B17-$B$16)/($B$41-$B$16) -> 0.3752 | G17: =G$16+(G$41-G$16)*($B17-$B$16)/($B$41-$B$16) -> 0.3752 | H17: =H$16+(H$41-H$16)*($B17-$B$16)/($B$41-$B$16) -> 0.3852
B18: =B17+0.01 -> 0.27 | C18: =C$16+(C$41-C$16)*($B18-$B$16)/($B$41-$B$16) -> 0.3588 | D18: =D$16+(D$41-D$16)*($B18-$B$16)/($B$41-$B$16) -> 0.3696 | E18: =E$16+(E$41-E$16)*($B18-$B$16)/($B$41-$B$16) -> 0.3704 | F18: =F$16+(F$41-F$16)*($B18-$B$16)/($B$41-$B$16) -> 0.3804 | G18: =G$16+(G$41-G$16)*($B18-$B$16)/($B$41-$B$16) -> 0.3804 | H18: =H$16+(H$41-H$16)*($B18-$B$16)/($B$41-$B$16) -> 0.3904
B19: =B18+0.01 -> 0.28 | C19: =C$16+(C$41-C$16)*($B19-$B$16)/($B$41-$B$16) -> 0.3632 | D19: =D$16+(D$41-D$16)*($B19-$B$16)/($B$41-$B$16) -> 0.3744 | E19: =E$16+(E$41-E$16)*($B19-$B$16)/($B$41-$B$16) -> 0.3756 | F19: =F$16+(F$41-F$16)*($B19-$B$16)/($B$41-$B$16) -> 0.3856 | G19: =G$16+(G$41-G$16)*($B19-$B$16)/($B$41-$B$16) -> 0.3856 | H19: =H$16+(H$41-H$16)*($B19-$B$16)/($B$41-$B$16) -> 0.3956
B20: =B19+0.01 -> 0.29 | C20: =C$16+(C$41-C$16)*($B20-$B$16)/($B$41-$B$16) -> 0.3676 | D20: =D$16+(D$41-D$16)*($B20-$B$16)/($B$41-$B$16) -> 0.3792 | E20: =E$16+(E$41-E$16)*($B20-$B$16)/($B$41-$B$16) -> 0.3808 | F20: =F$16+(F$41-F$16)*($B20-$B$16)/($B$41-$B$16) -> 0.3908 | G20: =G$16+(G$41-G$16)*($B20-$B$16)/($B$41-$B$16) -> 0.3908 | H20: =H$16+(H$41-H$16)*($B20-$B$16)/($B$41-$B$16) -> 0.4008
B21: =B20+0.01 -> 0.3 | C21: =C$16+(C$41-C$16)*($B21-$B$16)/($B$41-$B$16) -> 0.372 | D21: =D$16+(D$41-D$16)*($B21-$B$16)/($B$41-$B$16) -> 0.384 | E21: =E$16+(E$41-E$16)*($B21-$B$16)/($B$41-$B$16) -> 0.386 | F21: =F$16+(F$41-F$16)*($B21-$B$16)/($B$41-$B$16) -> 0.396 | G21: =G$16+(G$41-G$16)*($B21-$B$16)/($B$41-$B$16) -> 0.396 | H21: =H$16+(H$41-H$16)*($B21-$B$16)/($B$41-$B$16) -> 0.406
B22: =B21+0.01 -> 0.31 | C22: =C$16+(C$41-C$16)*($B22-$B$16)/($B$41-$B$16) -> 0.3764 | D22: =D$16+(D$41-D$16)*($B22-$B$16)/($B$41-$B$16) -> 0.3888 | E22: =E$16+(E$41-E$16)*($B22-$B$16)/($B$41-$B$16) -> 0.3912 | F22: =F$16+(F$41-F$16)*($B22-$B$16)/($B$41-$B$16) -> 0.4012 | G22: =G$16+(G$41-G$16)*($B22-$B$16)/($B$41-$B$16) -> 0.4012 | H22: =H$16+(H$41-H$16)*($B22-$B$16)/($B$41-$B$16) -> 0.4112
B23: =B22+0.01 -> 0.32 | C23: =C$16+(C$41-C$16)*($B23-$B$16)/($B$41-$B$16) -> 0.3808 | D23: =D$16+(D$41-D$16)*($B23-$B$16)/($B$41-$B$16) -> 0.3936 | E23: =E$16+(E$41-E$16)*($B23-$B$16)/($B$41-$B$16) -> 0.3964 | F23: =F$16+(F$41-F$16)*($B23-$B$16)/($B$41-$B$16) -> 0.4064 | G23: =G$16+(G$41-G$16)*($B23-$B$16)/($B$41-$B$16) -> 0.4064 | H23: =H$16+(H$41-H$16)*($B23-$B$16)/($B$41-$B$16) -> 0.4164
B24: =B23+0.01 -> 0.33 | C24: =C$16+(C$41-C$16)*($B24-$B$16)/($B$41-$B$16) -> 0.3852 | D24: =D$16+(D$41-D$16)*($B24-$B$16)/($B$41-$B$16) -> 0.3984 | E24: =E$16+(E$41-E$16)*($B24-$B$16)/($B$41-$B$16) -> 0.4016 | F24: =F$16+(F$41-F$16)*($B24-$B$16)/($B$41-$B$16) -> 0.4116 | G24: =G$16+(G$41-G$16)*($B24-$B$16)/($B$41-$B$16) -> 0.4116 | H24: =H$16+(H$41-H$16)*($B24-$B$16)/($B$41-$B$16) -> 0.4216
B25: =B24+0.01 -> 0.34 | C25: =C$16+(C$41-C$16)*($B25-$B$16)/($B$41-$B$16) -> 0.3896 | D25: =D$16+(D$41-D$16)*($B25-$B$16)/($B$41-$B$16) -> 0.4032 | E25: =E$16+(E$41-E$16)*($B25-$B$16)/($B$41-$B$16) -> 0.4068 | F25: =F$16+(F$41-F$16)*($B25-$B$16)/($B$41-$B$16) -> 0.4168 | G25: =G$16+(G$41-G$16)*($B25-$B$16)/($B$41-$B$16) -> 0.4168 | H25: =H$16+(H$41-H$16)*($B25-$B$16)/($B$41-$B$16) -> 0.4268
B26: =B25+0.01 -> 0.35 | C26: =C$16+(C$41-C$16)*($B26-$B$16)/($B$41-$B$16) -> 0.394 | D26: =D$16+(D$41-D$16)*($B26-$B$16)/($B$41-$B$16) -> 0.408 | E26: =E$16+(E$41-E$16)*($B26-$B$16)/($B$41-$B$16) -> 0.412 | F26: =F$16+(F$41-F$16)*($B26-$B$16)/($B$41-$B$16) -> 0.422 | G26: =G$16+(G$41-G$16)*($B26-$B$16)/($B$41-$B$16) -> 0.422 | H26: =H$16+(H$41-H$16)*($B26-$B$16)/($B$41-$B$16) -> 0.432
B27: =B26+0.01 -> 0.36 | C27: =C$16+(C$41-C$16)*($B27-$B$16)/($B$41-$B$16) -> 0.3984 | D27: =D$16+(D$41-D$16)*($B27-$B$16)/($B$41-$B$16) -> 0.4128 | E27: =E$16+(E$41-E$16)*($B27-$B$16)/($B$41-$B$16) -> 0.4172 | F27: =F$16+(F$41-F$16)*($B27-$B$16)/($B$41-$B$16) -> 0.4272 | G27: =G$16+(G$41-G$16)*($B27-$B$16)/($B$41-$B$16) -> 0.4272 | H27: =H$16+(H$41-H$16)*($B27-$B$16)/($B$41-$B$16) -> 0.4372
B28: =B27+0.01 -> 0.37 | C28: =C$16+(C$41-C$16)*($B28-$B$16)/($B$41-$B$16) -> 0.4028 | D28: =D$16+(D$41-D$16)*($B28-$B$16)/($B$41-$B$16) -> 0.4176 | E28: =E$16+(E$41-E$16)*($B28-$B$16)/($B$41-$B$16) -> 0.4224 | F28: =F$16+(F$41-F$16)*($B28-$B$16)/($B$41-$B$16) -> 0.4324 | G28: =G$16+(G$41-G$16)*($B28-$B$16)/($B$41-$B$16) -> 0.4324 | H28: =H$16+(H$41-H$16)*($B28-$B$16)/($B$41-$B$16) -> 0.4424
... B40: =B39+0.01 -> 0.49 | C40: =C$16+(C$41-C$16)*($B40-$B$16)/($B$41-$B$16) -> 0.4556 | D40: =D$16+(D$41-D$16)*($B40-$B$16)/($B$41-$B$16) -> 0.4752 | E40: =E$16+(E$41-E$16)*($B40-$B$16)/($B$41-$B$16) -> 0.4848 | F40: =F$16+(F$41-F$16)*($B40-$B$16)/($B$41-$B$16) -> 0.4948 | G40: =G$16+(G$41-G$16)*($B40-$B$16)/($B$41-$B$16) -> 0.4948 | H40: =H$16+(H$41-H$16)*($B40-$B$16)/($B$41-$B$16) -> 0.5048
B41: =B40+0.01 -> 0.5 | C41: 0.46 | D41: 0.48 | E41: 0.49 | F41: 0.5 | G41: 0.5 | H41: 0.51
B42: =B41+0.01 -> 0.51 | C42: =C$41+(C$66-C$41)*($B42-$B$41)/($B$66-$B$41) -> 0.4632 | D42: =D$41+(D$66-D$41)*($B42-$B$41)/($B$66-$B$41) -> 0.4832 | E42: =E$41+(E$66-E$41)*($B42-$B$41)/($B$66-$B$41) -> 0.4932 | F42: =F$41+(F$66-F$41)*($B42-$B$41)/($B$66-$B$41) -> 0.5036 | G42: =G$41+(G$66-G$41)*($B42-$B$41)/($B$66-$B$41) -> 0.5036 | H42: =H$41+(H$66-H$41)*($B42-$B$41)/($B$66-$B$41) -> 0.5136
B43: =B42+0.01 -> 0.52 | C43: =C$41+(C$66-C$41)*($B43-$B$41)/($B$66-$B$41) -> 0.4664 | D43: =D$41+(D$66-D$41)*($B43-$B$41)/($B$66-$B$41) -> 0.4864 | E43: =E$41+(E$66-E$41)*($B43-$B$41)/($B$66-$B$41) -> 0.4964 | F43: =F$41+(F$66-F$41)*($B43-$B$41)/($B$66-$B$41) -> 0.5072 | G43: =G$41+(G$66-G$41)*($B43-$B$41)/($B$66-$B$41) -> 0.5072 | H43: =H$41+(H$66-H$41)*($B43-$B$41)/($B$66-$B$41) -> 0.5172
B44: =B43+0.01 -> 0.53 | C44: =C$41+(C$66-C$41)*($B44-$B$41)/($B$66-$B$41) -> 0.4696 | D44: =D$41+(D$66-D$41)*($B44-$B$41)/($B$66-$B$41) -> 0.4896 | E44: =E$41+(E$66-E$41)*($B44-$B$41)/($B$66-$B$41) -> 0.4996 | F44: =F$41+(F$66-F$41)*($B44-$B$41)/($B$66-$B$41) -> 0.5108 | G44: =G$41+(G$66-G$41)*($B44-$B$41)/($B$66-$B$41) -> 0.5108 | H44: =H$41+(H$66-H$41)*($B44-$B$41)/($B$66-$B$41) -> 0.5208
B45: =B44+0.01 -> 0.54 | C45: =C$41+(C$66-C$41)*($B45-$B$41)/($B$66-$B$41) -> 0.4728 | D45: =D$41+(D$66-D$41)*($B45-$B$41)/($B$66-$B$41) -> 0.4928 | E45: =E$41+(E$66-E$41)*($B45-$B$41)/($B$66-$B$41) -> 0.5028 | F45: =F$41+(F$66-F$41)*($B45-$B$41)/($B$66-$B$41) -> 0.5144 | G45: =G$41+(G$66-G$41)*($B45-$B$41)/($B$66-$B$41) -> 0.5144 | H45: =H$41+(H$66-H$41)*($B45-$B$41)/($B$66-$B$41) -> 0.5244
B46: =B45+0.01 -> 0.55 | C46: =C$41+(C$66-C$41)*($B46-$B$41)/($B$66-$B$41) -> 0.476 | D46: =D$41+(D$66-D$41)*($B46-$B$41)/($B$66-$B$41) -> 0.496 | E46: =E$41+(E$66-E$41)*($B46-$B$41)/($B$66-$B$41) -> 0.506 | F46: =F$41+(F$66-F$41)*($B46-$B$41)/($B$66-$B$41) -> 0.518 | G46: =G$41+(G$66-G$41)*($B46-$B$41)/($B$66-$B$41) -> 0.518 | H46: =H$41+(H$66-H$41)*($B46-$B$41)/($B$66-$B$41) -> 0.528
B47: =B46+0.01 -> 0.56 | C47: =C$41+(C$66-C$41)*($B47-$B$41)/($B$66-$B$41) -> 0.4792 | D47: =D$41+(D$66-D$41)*($B47-$B$41)/($B$66-$B$41) -> 0.4992 | E47: =E$41+(E$66-E$41)*($B47-$B$41)/($B$66-$B$41) -> 0.5092 | F47: =F$41+(F$66-F$41)*($B47-$B$41)/($B$66-$B$41) -> 0.5216 | G47: =G$41+(G$66-G$41)*($B47-$B$41)/($B$66-$B$41) -> 0.5216 | H47: =H$41+(H$66-H$41)*($B47-$B$41)/($B$66-$B$41) -> 0.5316
B48: =B47+0.01 -> 0.57 | C48: =C$41+(C$66-C$41)*($B48-$B$41)/($B$66-$B$41) -> 0.4824 | D48: =D$41+(D$66-D$41)*($B48-$B$41)/($B$66-$B$41) -> 0.5024 | E48: =E$41+(E$66-E$41)*($B48-$B$41)/($B$66-$B$41) -> 0.5124 | F48: =F$41+(F$66-F$41)*($B48-$B$41)/($B$66-$B$41) -> 0.5252 | G48: =G$41+(G$66-G$41)*($B48-$B$41)/($B$66-$B$41) -> 0.5252 | H48: =H$41+(H$66-H$41)*($B48-$B$41)/($B$66-$B$41) -> 0.5352
B49: =B48+0.01 -> 0.58 | C49: =C$41+(C$66-C$41)*($B49-$B$41)/($B$66-$B$41) -> 0.4856 | D49: =D$41+(D$66-D$41)*($B49-$B$41)/($B$66-$B$41) -> 0.5056 | E49: =E$41+(E$66-E$41)*($B49-$B$41)/($B$66-$B$41) -> 0.5156 | F49: =F$41+(F$66-F$41)*($B49-$B$41)/($B$66-$B$41) -> 0.5288 | G49: =G$41+(G$66-G$41)*($B49-$B$41)/($B$66-$B$41) -> 0.5288 | H49: =H$41+(H$66-H$41)*($B49-$B$41)/($B$66-$B$41) -> 0.5388
B50: =B49+0.01 -> 0.59 | C50: =C$41+(C$66-C$41)*($B50-$B$41)/($B$66-$B$41) -> 0.4888 | D50: =D$41+(D$66-D$41)*($B50-$B$41)/($B$66-$B$41) -> 0.5088 | E50: =E$41+(E$66-E$41)*($B50-$B$41)/($B$66-$B$41) -> 0.5188 | F50: =F$41+(F$66-F$41)*($B50-$B$41)/($B$66-$B$41) -> 0.5324 | G50: =G$41+(G$66-G$41)*($B50-$B$41)/($B$66-$B$41) -> 0.5324 | H50: =H$41+(H$66-H$41)*($B50-$B$41)/($B$66-$B$41) -> 0.5424
B51: =B50+0.01 -> 0.6 | C51: =C$41+(C$66-C$41)*($B51-$B$41)/($B$66-$B$41) -> 0.492 | D51: =D$41+(D$66-D$41)*($B51-$B$41)/($B$66-$B$41) -> 0.512 | E51: =E$41+(E$66-E$41)*($B51-$B$41)/($B$66-$B$41) -> 0.522 | F51: =F$41+(F$66-F$41)*($B51-$B$41)/($B$66-$B$41) -> 0.536 | G51: =G$41+(G$66-G$41)*($B51-$B$41)/($B$66-$B$41) -> 0.536 | H51: =H$41+(H$66-H$41)*($B51-$B$41)/($B$66-$B$41) -> 0.546
...
